<sdf version='1.7'>
  <world name='default'>
    <light name='sun' type='directional'>
      <cast_shadows>1</cast_shadows>
      <pose>0 0 10 0 -0 0</pose>
      <diffuse>0.8 0.8 0.8 1</diffuse>
      <specular>0.2 0.2 0.2 1</specular>
      <attenuation>
        <range>1000</range>
        <constant>0.9</constant>
        <linear>0.01</linear>
        <quadratic>0.001</quadratic>
      </attenuation>
      <direction>-0.5 0.1 -0.9</direction>
      <spot>
        <inner_angle>0</inner_angle>
        <outer_angle>0</outer_angle>
        <falloff>0</falloff>
      </spot>
    </light>
    <model name='ground_plane'>
      <static>1</static>
      <link name='link'>
        <collision name='collision'>
          <geometry>
            <plane>
              <normal>0 0 1</normal>
              <size>100 100</size>
            </plane>
          </geometry>
          <surface>
            <contact>
              <collide_bitmask>65535</collide_bitmask>
              <ode/>
            </contact>
            <friction>
              <ode>
                <mu>100</mu>
                <mu2>50</mu2>
              </ode>
              <torsional>
                <ode/>
              </torsional>
            </friction>
            <bounce/>
          </surface>
          <max_contacts>10</max_contacts>
        </collision>
        <visual name='visual'>
          <cast_shadows>0</cast_shadows>
          <geometry>
            <plane>
              <normal>0 0 1</normal>
              <size>100 100</size>
            </plane>
          </geometry>
          <material>
            <script>
              <uri>file://media/materials/scripts/gazebo.material</uri>
              <name>Gazebo/Grey</name>
            </script>
          </material>
        </visual>
        <self_collide>0</self_collide>
        <enable_wind>0</enable_wind>
        <kinematic>0</kinematic>
      </link>
    </model>
    <gravity>0 0 -9.8</gravity>
    <magnetic_field>6e-06 2.3e-05 -4.2e-05</magnetic_field>
    <atmosphere type='adiabatic'/>
    <physics type='ode'>
      <max_step_size>0.001</max_step_size>
      <real_time_factor>1</real_time_factor>
      <real_time_update_rate>1000</real_time_update_rate>
    </physics>
    <scene>
      <ambient>0.4 0.4 0.4 1</ambient>
      <background>0.7 0.7 0.7 1</background>
      <shadows>1</shadows>
    </scene>
    <wind/>
    <spherical_coordinates>
      <surface_model>EARTH_WGS84</surface_model>
      <latitude_deg>0</latitude_deg>
      <longitude_deg>0</longitude_deg>
      <elevation>0</elevation>
      <heading_deg>0</heading_deg>
    </spherical_coordinates>
    <state world_name='default'>
      <sim_time>1585 207000000</sim_time>
      <real_time>452 605490342</real_time>
      <wall_time>1698071651 947658912</wall_time>
      <iterations>444164</iterations>
      <model name='clyinder_clone_0'>
        <pose>2.46904 8.92937 0.027448 1.57082 0.12293 1.42769</pose>
        <scale>1.09964 1.09964 0.675388</scale>
        <link name='link'>
          <pose>2.46904 8.92937 0.027448 1.57082 0.12293 1.42769</pose>
          <velocity>0.004155 0.024209 -0.004306 -0.881832 0.151342 1.4e-05</velocity>
          <acceleration>0 0 -9.8 -0 7e-06 0.033863</acceleration>
          <wrench>0 0 -0.294 0 -0 0</wrench>
        </link>
      </model>
      <model name='clyinder_clone_0_clone'>
        <pose>1.14286 0.172194 0.042394 0 -0 0</pose>
        <scale>0.652374 0.652374 1</scale>
        <link name='link'>
          <pose>1.14286 0.172194 0.042394 0 -0 0</pose>
          <velocity>0 0 0 0 -0 0</velocity>
          <acceleration>0 0 -9.8 0 -0 0</acceleration>
          <wrench>0 0 -0.294 0 -0 0</wrench>
        </link>
      </model>
      <model name='ground_plane'>
        <pose>0 0 0 0 -0 0</pose>
        <scale>1 1 1</scale>
        <link name='link'>
          <pose>0 0 0 0 -0 0</pose>
          <velocity>0 0 0 0 -0 0</velocity>
          <acceleration>0 0 0 0 -0 0</acceleration>
          <wrench>0 0 0 0 -0 0</wrench>
        </link>
      </model>
      <model name='robot'>
        <pose>1e-06 0 0 3e-06 -4e-06 3e-06</pose>
        <scale>1 1 1</scale>
        <link name='base_link'>
          <pose>1e-06 0 0 3e-06 -4e-06 3e-06</pose>
          <velocity>-0 -2e-06 0.000189 -0.000873 0.000895 3.9e-05</velocity>
          <acceleration>0.00322 0.038309 -0.003897 -1.14521 0.120631 0.049161</acceleration>
          <wrench>0.018959 0.225557 -0.022947 0 -0 0</wrench>
        </link>
        <link name='gripper_link1'>
          <pose>1.04293 0.129906 0.054513 -0.085845 -1.18353 -0.452162</pose>
          <velocity>-0.003242 -0.018518 -0.021508 0.159791 -0.072301 -2.80946</velocity>
          <acceleration>96.7854 312.154 10.3264 -1.92976 0.792819 -0.686004</acceleration>
          <wrench>3.79408 12.2368 0.404807 0 -0 0</wrench>
        </link>
        <link name='gripper_link2'>
          <pose>1.04306 0.211487 0.057074 0.061081 -1.21456 0.442134</pose>
          <velocity>-0.00132 -0.018233 -0.023792 0.155062 -0.076059 -2.80653</velocity>
          <acceleration>-79.4854 316.373 14.6183 -1.25242 0.162187 -2.25146</acceleration>
          <wrench>-3.11591 12.4021 0.573052 0 -0 0</wrench>
        </link>
        <link name='link1'>
          <pose>0.037511 0.145241 0.083993 7e-05 4.4e-05 -4e-05</pose>
          <velocity>-3.2e-05 0.000163 8.9e-05 -0.000528 0.000823 0.002293</velocity>
          <acceleration>-0.14516 0.349128 0.094829 2.97628 -0.404966 -2.03387</acceleration>
          <wrench>-0.348544 0.838291 0.227693 0 -0 0</wrench>
        </link>
        <link name='link2'>
          <pose>0.187514 0.145219 0.243968 -3.14093 1.14153 -3.14103</pose>
          <velocity>-0.000786 0.000191 -0.001317 -0.027039 0.014386 0.004738</velocity>
          <acceleration>-1.68922 -3.23176 -0.526806 2.55783 0.37308 -1.41473</acceleration>
          <wrench>-1.54455 -2.95499 -0.48169 0 -0 0</wrench>
        </link>
        <link name='link3'>
          <pose>0.486141 0.125149 0.062159 -0.000608 0.237288 -3.1e-05</pose>
          <velocity>-0.002921 -0.003342 -0.004957 -0.029385 0.02652 -0.01316</velocity>
          <acceleration>0.458503 -7.68866 -3.70566 2.6265 -1.24446 -0.712922</acceleration>
          <wrench>0.600685 -10.0729 -4.85478 0 -0 0</wrench>
        </link>
        <link name='link4'>
          <pose>0.690931 0.173181 0.084123 -0.000563 0.237367 -3.3e-05</pose>
          <velocity>-0.001666 -0.007452 -0.011217 -0.031552 0.025354 -0.017764</velocity>
          <acceleration>0.657472 -22.1263 -2.21128 0.470887 0.374613 -2.03499</acceleration>
          <wrench>0.41309 -13.902 -1.38935 0 -0 0</wrench>
        </link>
        <link name='link5'>
          <pose>0.847918 0.173184 0.066256 -0.001566 -1.19379 0.001552</pose>
          <velocity>-0.00211 -0.012574 -0.01479 -0.034337 0.042642 -0.023635</velocity>
          <acceleration>0.591363 -34.4202 -0.447497 -0.966614 1.05505 2.69978</acceleration>
          <wrench>0.224671 -13.0769 -0.170013 0 -0 0</wrench>
        </link>
        <link name='link6'>
          <pose>1.01015 0.170695 0.057562 -0.001313 -1.19394 0.001309</pose>
          <velocity>-0.002526 -0.017226 -0.021386 -0.034739 0.044615 -0.022944</velocity>
          <acceleration>0.656701 -39.1709 0.297417 -3.12933 -0.460364 -2.20683</acceleration>
          <wrench>0.051437 -3.06814 0.023296 0 -0 0</wrench>
        </link>
      </model>
      <light name='sun'>
        <pose>0 0 10 0 -0 0</pose>
      </light>
    </state>
    <gui fullscreen='0'>
      <camera name='user_camera'>
        <pose>0.976043 0.325146 1.06389 0 1.35543 -1.59334</pose>
        <view_controller>orbit</view_controller>
        <projection_type>perspective</projection_type>
      </camera>
    </gui>
    <model name='clyinder_clone_0'>
      <link name='link'>
        <inertial>
          <mass>0.03</mass>
          <inertia>
            <ixx>0.0001612</ixx>
            <ixy>0</ixy>
            <ixz>0</ixz>
            <iyy>0.0001612</iyy>
            <iyz>0</iyz>
            <izz>3.42e-05</izz>
          </inertia>
          <pose>0 0 0 0 -0 0</pose>
        </inertial>
        <self_collide>0</self_collide>
        <enable_wind>0</enable_wind>
        <kinematic>0</kinematic>
        <pose>-0 0 0 0 -0 0</pose>
        <gravity>1</gravity>
        <visual name='visual'>
          <geometry>
            <cylinder>
              <radius>0.024965</radius>
              <length>0.125541</length>
            </cylinder>
          </geometry>
          <material>
            <script>
              <name>Gazebo/Grey</name>
              <uri>file://media/materials/scripts/gazebo.material</uri>
            </script>
            <shader type='pixel'>
              <normal_map>__default__</normal_map>
            </shader>
            <ambient>1 0 0 0</ambient>
            <diffuse>1 0.7 0.7 1</diffuse>
            <specular>1 0.01 0.01 1</specular>
            <emissive>0 0 0 1</emissive>
          </material>
          <pose>0 0 0 0 -0 0</pose>
          <transparency>0</transparency>
          <cast_shadows>1</cast_shadows>
        </visual>
        <collision name='collision'>
          <laser_retro>0</laser_retro>
          <max_contacts>10</max_contacts>
          <pose>0 0 0 0 -0 0</pose>
          <geometry>
            <cylinder>
              <radius>0.024965</radius>
              <length>0.125541</length>
            </cylinder>
          </geometry>
          <surface>
            <friction>
              <ode>
                <mu>1</mu>
                <mu2>1</mu2>
                <fdir1>0 0 0</fdir1>
                <slip1>0</slip1>
                <slip2>0</slip2>
              </ode>
              <torsional>
                <coefficient>1</coefficient>
                <patch_radius>1000</patch_radius>
                <surface_radius>1000</surface_radius>
                <use_patch_radius>1</use_patch_radius>
                <ode>
                  <slip>-0.66</slip>
                </ode>
              </torsional>
            </friction>
            <bounce>
              <restitution_coefficient>1</restitution_coefficient>
              <threshold>1e+06</threshold>
            </bounce>
            <contact>
              <collide_without_contact>0</collide_without_contact>
              <collide_without_contact_bitmask>1</collide_without_contact_bitmask>
              <collide_bitmask>1</collide_bitmask>
              <ode>
                <soft_cfm>0</soft_cfm>
                <soft_erp>0.2</soft_erp>
                <kp>1e+13</kp>
                <kd>1</kd>
                <max_vel>0.31</max_vel>
                <min_depth>0</min_depth>
              </ode>
              <bullet>
                <split_impulse>1</split_impulse>
                <split_impulse_penetration_threshold>-0.01</split_impulse_penetration_threshold>
                <soft_cfm>0</soft_cfm>
                <soft_erp>0.2</soft_erp>
                <kp>1e+13</kp>
                <kd>1</kd>
              </bullet>
            </contact>
          </surface>
        </collision>
      </link>
      <static>0</static>
      <allow_auto_disable>1</allow_auto_disable>
      <pose>1.76144 0.130772 0.063299 0.012165 -0.018029 0.788589</pose>
    </model>
    <model name='robot'>
      <joint name='fix_joint' type='fixed'>
        <pose relative_to='__model__'>0 0 0 0 -0 0</pose>
        <parent>world</parent>
        <child>base_link</child>
      </joint>
      <link name='base_link'>
        <pose relative_to='fix_joint'>0 0 0 0 -0 0</pose>
        <inertial>
          <pose>0.038926 0.14666 0.038711 0 -0 0</pose>
          <mass>5.8879</mass>
          <inertia>
            <ixx>0.037229</ixx>
            <ixy>0.00081566</ixy>
            <ixz>-4.2093e-05</ixz>
            <iyy>0.037229</iyy>
            <iyz>-4.2093e-05</iyz>
            <izz>0.067975</izz>
          </inertia>
        </inertial>
        <collision name='base_link_collision'>
          <pose>0 0 0 0 -0 0</pose>
          <geometry>
            <mesh>
              <scale>1 1 1</scale>
              <uri>/home/bacha20/test/src/xis_kuka/meshes/base_link.STL</uri>
            </mesh>
          </geometry>
          <surface>
            <contact>
              <ode/>
            </contact>
            <friction>
              <ode/>
              <torsional>
                <ode/>
              </torsional>
            </friction>
            <bounce/>
          </surface>
          <max_contacts>10</max_contacts>
        </collision>
        <visual name='base_link_visual'>
          <pose>0 0 0 0 -0 0</pose>
          <geometry>
            <mesh>
              <scale>1 1 1</scale>
              <uri>/home/bacha20/test/src/xis_kuka/meshes/base_link.STL</uri>
            </mesh>
          </geometry>
          <material>
            <script>
              <name>Gazebo/Black</name>
              <uri>file://media/materials/scripts/gazebo.material</uri>
            </script>
          </material>
        </visual>
        <self_collide>0</self_collide>
        <enable_wind>0</enable_wind>
        <kinematic>0</kinematic>
      </link>
      <joint name='joint1' type='revolute'>
        <pose relative_to='base_link'>0.0375 0.14524 0.084 0 -0 0</pose>
        <parent>base_link</parent>
        <child>link1</child>
        <axis>
          <xyz>0 0 1</xyz>
          <limit>
            <lower>-3.14159</lower>
            <upper>3.14159</upper>
            <effort>300</effort>
            <velocity>1</velocity>
          </limit>
          <dynamics>
            <spring_reference>0</spring_reference>
            <spring_stiffness>0</spring_stiffness>
          </dynamics>
        </axis>
      </joint>
      <link name='link1'>
        <pose relative_to='joint1'>0 0 0 0 -0 0</pose>
        <inertial>
          <pose>0.055474 0.001908 0.082225 0 -0 0</pose>
          <mass>2.4011</mass>
          <inertia>
            <ixx>0.012303</ixx>
            <ixy>-0.00064066</ixy>
            <ixz>-0.0093653</ixz>
            <iyy>0.024564</iyy>
            <iyz>-0.0004856</iyz>
            <izz>0.016929</izz>
          </inertia>
        </inertial>
        <collision name='link1_collision'>
          <pose>0 0 0 0 -0 0</pose>
          <geometry>
            <mesh>
              <scale>1 1 1</scale>
              <uri>/home/bacha20/test/src/xis_kuka/meshes/link1.STL</uri>
            </mesh>
          </geometry>
          <surface>
            <contact>
              <ode/>
            </contact>
            <friction>
              <ode/>
              <torsional>
                <ode/>
              </torsional>
            </friction>
            <bounce/>
          </surface>
          <max_contacts>10</max_contacts>
        </collision>
        <visual name='link1_visual'>
          <pose>0 0 0 0 -0 0</pose>
          <geometry>
            <mesh>
              <scale>1 1 1</scale>
              <uri>/home/bacha20/test/src/xis_kuka/meshes/link1.STL</uri>
            </mesh>
          </geometry>
          <material>
            <script>
              <name>Gazebo/White</name>
              <uri>file://media/materials/scripts/gazebo.material</uri>
            </script>
          </material>
        </visual>
        <self_collide>0</self_collide>
        <enable_wind>0</enable_wind>
        <kinematic>0</kinematic>
      </link>
      <joint name='joint2' type='revolute'>
        <pose relative_to='link1'>0.15 0 0.16 0 -0 0</pose>
        <parent>link1</parent>
        <child>link2</child>
        <axis>
          <xyz>0 1 0</xyz>
          <limit>
            <lower>-1.8</lower>
            <upper>2</upper>
            <effort>300</effort>
            <velocity>1</velocity>
          </limit>
          <dynamics>
            <spring_reference>0</spring_reference>
            <spring_stiffness>0</spring_stiffness>
          </dynamics>
        </axis>
      </joint>
      <link name='link2'>
        <pose relative_to='joint2'>0 0 0 0 -0 0</pose>
        <inertial>
          <pose>0.008504 -0.035227 0.13926 0 -0 0</pose>
          <mass>0.91436</mass>
          <inertia>
            <ixx>0.017632</ixx>
            <ixy>2.2762e-05</ixy>
            <ixz>-0.0018403</ixz>
            <iyy>0.018167</iyy>
            <iyz>-8.6035e-05</iyz>
            <izz>0.00081686</izz>
          </inertia>
        </inertial>
        <collision name='link2_collision'>
          <pose>0 0 0 0 -0 0</pose>
          <geometry>
            <mesh>
              <scale>1 1 1</scale>
              <uri>/home/bacha20/test/src/xis_kuka/meshes/link2.STL</uri>
            </mesh>
          </geometry>
          <surface>
            <contact>
              <ode/>
            </contact>
            <friction>
              <ode/>
              <torsional>
                <ode/>
              </torsional>
            </friction>
            <bounce/>
          </surface>
          <max_contacts>10</max_contacts>
        </collision>
        <visual name='link2_visual'>
          <pose>0 0 0 0 -0 0</pose>
          <geometry>
            <mesh>
              <scale>1 1 1</scale>
              <uri>/home/bacha20/test/src/xis_kuka/meshes/link2.STL</uri>
            </mesh>
          </geometry>
          <material>
            <script>
              <name>Gazebo/White</name>
              <uri>file://media/materials/scripts/gazebo.material</uri>
            </script>
          </material>
        </visual>
        <self_collide>0</self_collide>
        <enable_wind>0</enable_wind>
        <kinematic>0</kinematic>
      </link>
      <joint name='joint3' type='revolute'>
        <pose relative_to='link2'>0.041011 -0.02 0.34719 0 -0 0</pose>
        <parent>link2</parent>
        <child>link3</child>
        <axis>
          <xyz>0 1 0</xyz>
          <limit>
            <lower>-2</lower>
            <upper>1.2</upper>
            <effort>300</effort>
            <velocity>1</velocity>
          </limit>
          <dynamics>
            <spring_reference>0</spring_reference>
            <spring_stiffness>0</spring_stiffness>
          </dynamics>
        </axis>
      </joint>
      <link name='link3'>
        <pose relative_to='joint3'>0 0 0 0 -0 0</pose>
        <inertial>
          <pose>0.029812 0.0459 0.042503 0 -0 0</pose>
          <mass>1.3101</mass>
          <inertia>
            <ixx>0.0019297</ixx>
            <ixy>-8.0363e-05</ixy>
            <ixz>-0.00085045</ixz>
            <iyy>0.0067673</iyy>
            <iyz>-0.00013415</iyz>
            <izz>0.0062137</izz>
          </inertia>
        </inertial>
        <collision name='link3_collision'>
          <pose>0 0 0 0 -0 0</pose>
          <geometry>
            <mesh>
              <scale>1 1 1</scale>
              <uri>/home/bacha20/test/src/xis_kuka/meshes/link3.STL</uri>
            </mesh>
          </geometry>
          <surface>
            <contact>
              <ode/>
            </contact>
            <friction>
              <ode/>
              <torsional>
                <ode/>
              </torsional>
            </friction>
            <bounce/>
          </surface>
          <max_contacts>10</max_contacts>
        </collision>
        <visual name='link3_visual'>
          <pose>0 0 0 0 -0 0</pose>
          <geometry>
            <mesh>
              <scale>1 1 1</scale>
              <uri>/home/bacha20/test/src/xis_kuka/meshes/link3.STL</uri>
            </mesh>
          </geometry>
          <material>
            <script>
              <name>Gazebo/White</name>
              <uri>file://media/materials/scripts/gazebo.material</uri>
            </script>
          </material>
        </visual>
        <self_collide>0</self_collide>
        <enable_wind>0</enable_wind>
        <kinematic>0</kinematic>
      </link>
      <joint name='joint4' type='revolute'>
        <pose relative_to='link3'>0.19388 0.048 0.069558 0 -0 0</pose>
        <parent>link3</parent>
        <child>link4</child>
        <axis>
          <xyz>-0.99229 0 -0.1239</xyz>
          <limit>
            <lower>-3.14159</lower>
            <upper>3.14159</upper>
            <effort>300</effort>
            <velocity>1</velocity>
          </limit>
          <dynamics>
            <spring_reference>0</spring_reference>
            <spring_stiffness>0</spring_stiffness>
          </dynamics>
        </axis>
      </joint>
      <link name='link4'>
        <pose relative_to='joint4'>0 0 0 0 -0 0</pose>
        <inertial>
          <pose>0.099197 0 0.012386 0 -0 0</pose>
          <mass>0.6283</mass>
          <inertia>
            <ixx>0.00060709</ixx>
            <ixy>-1.907e-10</ixy>
            <ixz>-0.00019626</ixz>
            <iyy>0.0020116</iyy>
            <iyz>-1.7578e-10</iyz>
            <izz>0.0021543</izz>
          </inertia>
        </inertial>
        <collision name='link4_collision'>
          <pose>0 0 0 0 -0 0</pose>
          <geometry>
            <mesh>
              <scale>1 1 1</scale>
              <uri>/home/bacha20/test/src/xis_kuka/meshes/link4.STL</uri>
            </mesh>
          </geometry>
          <surface>
            <contact>
              <ode/>
            </contact>
            <friction>
              <ode/>
              <torsional>
                <ode/>
              </torsional>
            </friction>
            <bounce/>
          </surface>
          <max_contacts>10</max_contacts>
        </collision>
        <visual name='link4_visual'>
          <pose>0 0 0 0 -0 0</pose>
          <geometry>
            <mesh>
              <scale>1 1 1</scale>
              <uri>/home/bacha20/test/src/xis_kuka/meshes/link4.STL</uri>
            </mesh>
          </geometry>
          <material>
            <script>
              <name>Gazebo/White</name>
              <uri>file://media/materials/scripts/gazebo.material</uri>
            </script>
          </material>
        </visual>
        <self_collide>0</self_collide>
        <enable_wind>0</enable_wind>
        <kinematic>0</kinematic>
      </link>
      <joint name='joint5' type='revolute'>
        <pose relative_to='link4'>0.15678 0 0.019577 0 -0 0</pose>
        <parent>link4</parent>
        <child>link5</child>
        <axis>
          <xyz>0 -1 0</xyz>
          <limit>
            <lower>-0.15</lower>
            <upper>3.5</upper>
            <effort>300</effort>
            <velocity>1</velocity>
          </limit>
          <dynamics>
            <spring_reference>0</spring_reference>
            <spring_stiffness>0</spring_stiffness>
          </dynamics>
        </axis>
      </joint>
      <link name='link5'>
        <pose relative_to='joint5'>0 0 0 0 -0 0</pose>
        <inertial>
          <pose>0.035198 -0.002837 -0.10495 0 -0 0</pose>
          <mass>0.37992</mass>
          <inertia>
            <ixx>0.00092038</ixx>
            <ixy>-4.5116e-06</ixy>
            <ixz>0.00022914</ixz>
            <iyy>0.0010045</iyy>
            <iyz>1.3453e-05</iyz>
            <izz>0.00031398</izz>
          </inertia>
        </inertial>
        <collision name='link5_collision'>
          <pose>0 0 0 0 -0 0</pose>
          <geometry>
            <mesh>
              <scale>1 1 1</scale>
              <uri>/home/bacha20/test/src/xis_kuka/meshes/link5.STL</uri>
            </mesh>
          </geometry>
          <surface>
            <contact>
              <ode/>
            </contact>
            <friction>
              <ode/>
              <torsional>
                <ode/>
              </torsional>
            </friction>
            <bounce/>
          </surface>
          <max_contacts>10</max_contacts>
        </collision>
        <visual name='link5_visual'>
          <pose>0 0 0 0 -0 0</pose>
          <geometry>
            <mesh>
              <scale>1 1 1</scale>
              <uri>/home/bacha20/test/src/xis_kuka/meshes/link5.STL</uri>
            </mesh>
          </geometry>
          <material>
            <script>
              <name>Gazebo/White</name>
              <uri>file://media/materials/scripts/gazebo.material</uri>
            </script>
          </material>
        </visual>
        <self_collide>0</self_collide>
        <enable_wind>0</enable_wind>
        <kinematic>0</kinematic>
      </link>
      <joint name='joint6' type='revolute'>
        <pose relative_to='link5'>0.051656 -0.0025 -0.15403 0 -0 0</pose>
        <parent>link5</parent>
        <child>link6</child>
        <axis>
          <xyz>0.31797 0 -0.9481</xyz>
          <limit>
            <lower>-3.14159</lower>
            <upper>3.14159</upper>
            <effort>300</effort>
            <velocity>1</velocity>
          </limit>
          <dynamics>
            <spring_reference>0</spring_reference>
            <spring_stiffness>0</spring_stiffness>
          </dynamics>
        </axis>
      </joint>
      <link name='link6'>
        <pose relative_to='joint6'>0 0 0 0 -0 0</pose>
        <inertial>
          <pose>0.005203 -0 -0.015515 0 -0 0</pose>
          <mass>0.078327</mass>
          <inertia>
            <ixx>3.9758e-05</ixx>
            <ixy>-2.0567e-07</ixy>
            <ixz>-6.2372e-07</ixz>
            <iyy>3.2776e-05</iyy>
            <iyz>-6.8975e-08</iyz>
            <izz>4.1409e-05</izz>
          </inertia>
        </inertial>
        <collision name='link6_collision'>
          <pose>0 0 0 0 -0 0</pose>
          <geometry>
            <mesh>
              <scale>1 1 1</scale>
              <uri>/home/bacha20/test/src/xis_kuka/meshes/link6.STL</uri>
            </mesh>
          </geometry>
          <surface>
            <contact>
              <ode/>
            </contact>
            <friction>
              <ode/>
              <torsional>
                <ode/>
              </torsional>
            </friction>
            <bounce/>
          </surface>
          <max_contacts>10</max_contacts>
        </collision>
        <visual name='link6_visual'>
          <pose>0 0 0 0 -0 0</pose>
          <geometry>
            <mesh>
              <scale>1 1 1</scale>
              <uri>/home/bacha20/test/src/xis_kuka/meshes/link6.STL</uri>
            </mesh>
          </geometry>
          <material>
            <script>
              <name>Gazebo/White</name>
              <uri>file://media/materials/scripts/gazebo.material</uri>
            </script>
          </material>
        </visual>
        <self_collide>0</self_collide>
        <enable_wind>0</enable_wind>
        <kinematic>0</kinematic>
      </link>
      <joint name='gripper_joint1' type='revolute'>
        <pose relative_to='link6'>0.009221 -0.040789 -0.0316 0 -0 0</pose>
        <parent>link6</parent>
        <child>gripper_link1</child>
        <axis>
          <xyz>-0.94762 0.031978 -0.3178</xyz>
          <limit>
            <lower>0</lower>
            <upper>1.2</upper>
            <effort>1</effort>
            <velocity>1</velocity>
          </limit>
          <dynamics>
            <spring_reference>0</spring_reference>
            <spring_stiffness>0</spring_stiffness>
          </dynamics>
        </axis>
      </joint>
      <link name='gripper_link1'>
        <pose relative_to='gripper_joint1'>0 0 0 0 -0 0</pose>
        <inertial>
          <pose>0.016686 0.013884 -0.048356 0 -0 0</pose>
          <mass>0.039201</mass>
          <inertia>
            <ixx>4.2037e-05</ixx>
            <ixy>-2.3802e-06</ixy>
            <ixz>1.2708e-05</ixz>
            <iyy>4.3626e-05</iyy>
            <iyz>6.82e-06</iyz>
            <izz>9.1738e-06</izz>
          </inertia>
        </inertial>
        <collision name='gripper_link1_collision'>
          <pose>0 0 0 0 -0 0</pose>
          <geometry>
            <mesh>
              <scale>1 1 1</scale>
              <uri>/home/bacha20/test/src/xis_kuka/meshes/gripper_link1.STL</uri>
            </mesh>
          </geometry>
          <surface>
            <contact>
              <ode/>
            </contact>
            <friction>
              <ode/>
              <torsional>
                <ode/>
              </torsional>
            </friction>
            <bounce/>
          </surface>
          <max_contacts>10</max_contacts>
        </collision>
        <visual name='gripper_link1_visual'>
          <pose>0 0 0 0 -0 0</pose>
          <geometry>
            <mesh>
              <scale>1 1 1</scale>
              <uri>/home/bacha20/test/src/xis_kuka/meshes/gripper_link1.STL</uri>
            </mesh>
          </geometry>
          <material>
            <script>
              <name>Gazebo/Black</name>
              <uri>file://media/materials/scripts/gazebo.material</uri>
            </script>
          </material>
        </visual>
        <self_collide>0</self_collide>
        <enable_wind>0</enable_wind>
        <kinematic>0</kinematic>
      </link>
      <joint name='gripper_joint2' type='revolute'>
        <pose relative_to='link6'>0.011696 0.040789 -0.03077 0 -0 0</pose>
        <parent>link6</parent>
        <child>gripper_link2</child>
        <axis>
          <xyz>0.94762 -0.031978 0.3178</xyz>
          <limit>
            <lower>0</lower>
            <upper>1.2</upper>
            <effort>1</effort>
            <velocity>1</velocity>
          </limit>
          <dynamics>
            <spring_reference>0</spring_reference>
            <spring_stiffness>0</spring_stiffness>
          </dynamics>
        </axis>
      </joint>
      <link name='gripper_link2'>
        <pose relative_to='gripper_joint2'>0 0 0 0 -0 0</pose>
        <inertial>
          <pose>0.015812 -0.014147 -0.048572 0 -0 0</pose>
          <mass>0.039201</mass>
          <inertia>
            <ixx>4.2327e-05</ixx>
            <ixy>2.2742e-06</ixy>
            <ixz>1.2311e-05</ixz>
            <iyy>4.3551e-05</iyy>
            <iyz>-7.0657e-06</iyz>
            <izz>8.9591e-06</izz>
          </inertia>
        </inertial>
        <collision name='gripper_link2_collision'>
          <pose>0 0 0 0 -0 0</pose>
          <geometry>
            <mesh>
              <scale>1 1 1</scale>
              <uri>/home/bacha20/test/src/xis_kuka/meshes/gripper_link2.STL</uri>
            </mesh>
          </geometry>
          <surface>
            <contact>
              <ode/>
            </contact>
            <friction>
              <ode/>
              <torsional>
                <ode/>
              </torsional>
            </friction>
            <bounce/>
          </surface>
          <max_contacts>10</max_contacts>
        </collision>
        <visual name='gripper_link2_visual'>
          <pose>0 0 0 0 -0 0</pose>
          <geometry>
            <mesh>
              <scale>1 1 1</scale>
              <uri>/home/bacha20/test/src/xis_kuka/meshes/gripper_link2.STL</uri>
            </mesh>
          </geometry>
          <material>
            <script>
              <name>Gazebo/Black</name>
              <uri>file://media/materials/scripts/gazebo.material</uri>
            </script>
          </material>
        </visual>
        <self_collide>0</self_collide>
        <enable_wind>0</enable_wind>
        <kinematic>0</kinematic>
      </link>
      <plugin name='gazebo_ros_control' filename='libgazebo_ros_control.so'>
        <robotNamespace>/</robotNamespace>
        <legacyModeNS>0</legacyModeNS>
      </plugin>
      <static>0</static>
      <plugin name='gazebo_grasp_fix' filename='libgazebo_grasp_fix.so'>
        <arm>
          <arm_name>arm</arm_name>
          <palm_link>link6</palm_link>
          <gripper_link>gripper_link1</gripper_link>
          <gripper_link>gripper_link2</gripper_link>
        </arm>
        <forces_angle_tolerance>100</forces_angle_tolerance>
        <update_rate>4</update_rate>
        <grip_count_threshold>4</grip_count_threshold>
        <max_grip_count>8</max_grip_count>
        <release_tolerance>0.005</release_tolerance>
        <disable_collisions_on_attach>0</disable_collisions_on_attach>
        <contact_topic>__default_topic__</contact_topic>
        <robotNamespace>/</robotNamespace>
      </plugin>
      <pose>0 0 0 0 -0 0</pose>
    </model>
    <model name='clyinder_clone_0_clone'>
      <link name='link'>
        <inertial>
          <mass>0.03</mass>
          <inertia>
            <ixx>0.0001612</ixx>
            <ixy>0</ixy>
            <ixz>0</ixz>
            <iyy>0.0001612</iyy>
            <iyz>0</iyz>
            <izz>3.42e-05</izz>
          </inertia>
          <pose>0 0 0 0 -0 0</pose>
        </inertial>
        <self_collide>0</self_collide>
        <enable_wind>0</enable_wind>
        <kinematic>0</kinematic>
        <pose>-0 0 0 0 -0 0</pose>
        <gravity>1</gravity>
        <visual name='visual'>
          <geometry>
            <cylinder>
              <radius>0.0274525</radius>
              <length>0.0847889</length>
            </cylinder>
          </geometry>
          <material>
            <script>
              <name>Gazebo/Grey</name>
              <uri>file://media/materials/scripts/gazebo.material</uri>
            </script>
            <shader type='pixel'>
              <normal_map>__default__</normal_map>
            </shader>
            <ambient>1 0 0 0</ambient>
            <diffuse>1 0.7 0.7 1</diffuse>
            <specular>1 0.01 0.01 1</specular>
            <emissive>0 0 0 1</emissive>
          </material>
          <pose>0 0 0 0 -0 0</pose>
          <transparency>0</transparency>
          <cast_shadows>1</cast_shadows>
        </visual>
        <collision name='collision'>
          <laser_retro>0</laser_retro>
          <max_contacts>10</max_contacts>
          <pose>0 0 0 0 -0 0</pose>
          <geometry>
            <cylinder>
              <radius>0.0274525</radius>
              <length>0.0847889</length>
            </cylinder>
          </geometry>
          <surface>
            <friction>
              <ode>
                <mu>1</mu>
                <mu2>1</mu2>
                <fdir1>0 0 0</fdir1>
                <slip1>0</slip1>
                <slip2>0</slip2>
              </ode>
              <torsional>
                <coefficient>1</coefficient>
                <patch_radius>1000</patch_radius>
                <surface_radius>1000</surface_radius>
                <use_patch_radius>1</use_patch_radius>
                <ode>
                  <slip>-0.66</slip>
                </ode>
              </torsional>
            </friction>
            <bounce>
              <restitution_coefficient>1</restitution_coefficient>
              <threshold>1e+06</threshold>
            </bounce>
            <contact>
              <collide_without_contact>0</collide_without_contact>
              <collide_without_contact_bitmask>1</collide_without_contact_bitmask>
              <collide_bitmask>1</collide_bitmask>
              <ode>
                <soft_cfm>0</soft_cfm>
                <soft_erp>0.2</soft_erp>
                <kp>1e+13</kp>
                <kd>1</kd>
                <max_vel>0.31</max_vel>
                <min_depth>0</min_depth>
              </ode>
              <bullet>
                <split_impulse>1</split_impulse>
                <split_impulse_penetration_threshold>-0.01</split_impulse_penetration_threshold>
                <soft_cfm>0</soft_cfm>
                <soft_erp>0.2</soft_erp>
                <kp>1e+13</kp>
                <kd>1</kd>
              </bullet>
            </contact>
          </surface>
        </collision>
      </link>
      <static>0</static>
      <allow_auto_disable>1</allow_auto_disable>
      <pose>1.00819 -0.036262 0.027453 -1.5708 -1.00673 -1.7139</pose>
    </model>
  </world>
</sdf>
